Workbook

Sheet Samples list
B2: Sample number | C2: Sample name
B3: 1 | C3: Secco 1
B4: 2 | C4: Secco 2
B5: 3 | C5: Umido 1
B6: 4 | C6: Umido 2
B7: 5 | C7: Fanghi 1
B8: 6 | C8: Fanghi 2

Sheet Moisture
B1: as received sample | G1: stabilized sample
B3: =IF(ISBLANK('Samples list'!C3),"n.d.",'Samples list'!C3) -> Secco 1 | G3: =B3 -> Secco 1
B4: Tare [g] | C4: Gross ar [g] | D4: Gross dry [g] | E4: Moisture (sample) | G4: Tare [g] | H4: Gross stabilized [g] | I4: Gross dry [g] | J4: Moisture (stabilized sample)
B5: 1.29 | C5: 2.306 | D5: 2.239 | E5: =(C5-D5)/(C5-B5) -> 0.065944882 | G5: 1.306 | H5: =G5+1.389 -> 2.695 | I5: 2.657 | J5: =(H5-I5)/(H5-G5) -> 0.027357811
B6: 1.275 | C6: 2.64 | D6: 2.549 | E6: =(C6-D6)/(C6-B6) -> 0.066666667 | G6: 1.272 | H6: =G6+1.884 -> 3.156 | I6: 3.107 | J6: =(H6-I6)/(H6-G6) -> 0.026008493
B7: 1.286 | C7: 2.963 | D7: 2.852 | E7: =(C7-D7)/(C7-B7) -> 0.066189624 | G7: 1.303 | H7: =G7+1.263 -> 2.566 | I7: 2.536 | J7: =(H7-I7)/(H7-G7) -> 0.023752969
D8: av. | E8: =AVERAGE(E5:E7) -> 0.066267058 | I8: av. | J8: =AVERAGE(J5:J7) -> 0.025706424
D9: dev. | E9: =_xlfn.STDEV.P(E5:E7) -> 0.00029971125 | I9: dev. | J9: =_xlfn.STDEV.P(J5:J7) -> 0.0014870902
B11: =IF(ISBLANK('Samples list'!C4),"n.d.",'Samples list'!C4) -> Secco 2 | G11: =B11 -> Secco 2
B12: Tare [g] | C12: Gross ar [g] | D12: Gross dry [g] | E12: Moisture (sample) | G12: Tare [g] | H12: Gross stabilized [g] | I12: Gross dry [g] | J12: Moisture (stabilized sample)
B13: 1.286 | C13: 2.632 | D13: 2.454 | E13: =(C13-D13)/(C13-B13) -> 0.13224368 | G13: 1.308 | H13: =G13+1.462 -> 2.77 | I13: 2.725 | J13: =(H13-I13)/(H13-G13) -> 0.030779754
B14: 1.295 | C14: 2.369 | D14: 2.23 | E14: =(C14-D14)/(C14-B14) -> 0.12942272 | G14: 1.296 | H14: =G14+1.939 -> 3.235 | I14: 3.177 | J14: =(H14-I14)/(H14-G14) -> 0.029912326
B15: 1.273 | C15: 3.137 | D15: 2.916 | E15: =(C15-D15)/(C15-B15) -> 0.11856223 | G15: 1.28 | H15: =G15+1.288 -> 2.568 | I15: 2.529 | J15: =(H15-I15)/(H15-G15) -> 0.030279503
D16: av. | E16: =AVERAGE(E13:E15) -> 0.12674288 | I16: av. | J16: =AVERAGE(J13:J15) -> 0.030323861
D17: dev. | E17: =_xlfn.STDEV.P(E13:E15) -> 0.0058981183 | I17: dev. | J17: =_xlfn.STDEV.P(J13:J15) -> 0.00035551228
B19: =IF(ISBLANK('Samples list'!C5),"n.d.",'Samples list'!C5) -> Umido 1 | G19: =B19 -> Umido 1
B20: Tare [g] | C20: Gross ar [g] | D20: Gross dry [g] | E20: Moisture (sample) | G20: Tare [g] | H20: Gross stabilized [g] | I20: Gross dry [g] | J20: Moisture (stabilized sample)
B21: 1.297 | C21: 3.091 | D21: 1.676 | E21: =(C21-D21)/(C21-B21) -> 0.78874025 | G21: 1.278 | H21: =G21+1.797 -> 3.075 | I21: 3.016 | J21: =(H21-I21)/(H21-G21) -> 0.032832499
B22: 1.292 | C22: 2.929 | D22: 1.68 | E22: =(C22-D22)/(C22-B22) -> 0.76298106 | G22: 1.288 | H22: =G22+1.797 -> 3.085 | I22: 3.017 | J22: =(H22-I22)/(H22-G22) -> 0.037840846
B23: 1.294 | C23: 3.227 | D23: 1.696 | E23: =(C23-D23)/(C23-B23) -> 0.79203311 | G23: 1.294 | H23: =G23+1.786 -> 3.08 | I23: 3.012 | J23: =(H23-I23)/(H23-G23) -> 0.038073908
D24: av. | E24: =AVERAGE(E21:E23) -> 0.78125147 | I24: av. | J24: =AVERAGE(J21:J23) -> 0.036249084
D25: dev. | E25: =_xlfn.STDEV.P(E21:E23) -> 0.012988883 | I25: dev. | J25: =_xlfn.STDEV.P(J21:J23) -> 0.0024177638
B27: =IF(ISBLANK('Samples list'!C6),"n.d.",'Samples list'!C6) -> Umido 2 | G27: =B27 -> Umido 2
B28: Tare [g] | C28: Gross ar [g] | D28: Gross dry [g] | E28: Moisture (sample) | G28: Tare [g] | H28: Gross stabilized [g] | I28: Gross dry [g] | J28: Moisture (stabilized sample)
B29: 1.286 | C29: 2.629 | D29: 1.684 | E29: =(C29-D29)/(C29-B29) -> 0.70364855 | G29: 1.277 | H29: =G29+1.021 -> 2.298 | I29: 2.278 | J29: =(H29-I29)/(H29-G29) -> 0.019588639
B30: 1.28 | C30: 3.142 | D30: 1.818 | E30: =(C30-D30)/(C30-B30) -> 0.71106337 | G30: 1.293 | H30: =G30+1.134 -> 2.427 | I30: 2.412 | J30: =(H30-I30)/(H30-G30) -> 0.013227513
B31: 1.291 | C31: 2.744 | D31: 1.736 | E31: =(C31-D31)/(C31-B31) -> 0.6937371 | G31: 1.307 | H31: =G31+1.235 -> 2.542 | I31: 2.526 | J31: =(H31-I31)/(H31-G31) -> 0.012955466
D32: av. | E32: =AVERAGE(E29:E31) -> 0.70281634 | I32: av. | J32: =AVERAGE(J29:J31) -> 0.015257206
D33: dev. | E33: =_xlfn.STDEV.P(E29:E31) -> 0.0070978588 | I33: dev. | J33: =_xlfn.STDEV.P(J29:J31) -> 0.0030647985
B35: =IF(ISBLANK('Samples list'!C7),"n.d.",'Samples list'!C7) -> Fanghi 1 | G35: =B35 -> Fanghi 1
B36: Tare [g] | C36: Gross ar [g] | D36: Gross dry [g] | E36: Moisture (sample) | G36: Tare [g] | H36: Gross stabilized [g] | I36: Gross dry [g] | J36: Moisture (stabilized sample)
B37: 1.306 | C37: 3.017 | D37: 1.561 | E37: =(C37-D37)/(C37-B37) -> 0.85096435 | G37: 1.285 | H37: =G37+1.963 -> 3.248 | I37: 3.189 | J37: =(H37-I37)/(H37-G37) -> 0.030056037
B38: 1.272 | C38: 3.143 | D38: 1.55 | E38: =(C38-D38)/(C38-B38) -> 0.85141635 | G38: 1.28 | H38: =G38+1.935 -> 3.215 | I38: 3.153 | J38: =(H38-I38)/(H38-G38) -> 0.032041344
B39: 1.282 | C39: 3.054 | D39: 1.543 | E39: =(C39-D39)/(C39-B39) -> 0.8527088 | G39: 1.291 | H39: =G39+1.9 -> 3.191 | I39: 3.134 | J39: =(H39-I39)/(H39-G39) -> 0.03
D40: av. | E40: =AVERAGE(E37:E39) -> 0.8516965 | I40: av. | J40: =AVERAGE(J37:J39) -> 0.030699127
D41: dev. | E41: =_xlfn.STDEV.P(E37:E39) -> 0.00073920812 | I41: dev. | J41: =_xlfn.STDEV.P(J37:J39) -> 0.00094936633
B43: =IF(ISBLANK('Samples list'!C8),"n.d.",'Samples list'!C8) -> Fanghi 2 | G43: =B43 -> Fanghi 2
B44: Tare [g] | C44: Gross ar [g] | D44: Gross dry [g] | E44: Moisture (sample) | G44: Tare [g] | H44: Gross stabilized [g] | I44: Gross dry [g] | J44: Moisture (stabilized sample)
B45: 1.308 | C45: 2.394 | D45: 1.464 | E45: =(C45-D45)/(C45-B45) -> 0.85635359 | G45: 1.286 | H45: =G45+1.565 -> 2.851 | I45: 2.811 | J45: =(H45-I45)/(H45-G45) -> 0.025559105
B46: 1.296 | C46: 2.642 | D46: 1.491 | E46: =(C46-D46)/(C46-B46) -> 0.8551263 | G46: 1.293 | H46: =G46+1.699 -> 2.992 | I46: 2.947 | J46: =(H46-I46)/(H46-G46) -> 0.026486168
...

Sheet Ash
B1: samples ar | H1: stabilized samples
B3: =Moisture!B3 -> Secco 1 | H3: =Moisture!B3 -> Secco 1
B4: Tare [g] | C4: Gross before [g] | D4: Gross after [g] | E4: Ash | H4: Tare [g] | I4: Gross before [g] | J4: Gross after [g] | K4: Ash
B5: 24.479 | C5: =B5+0.52 -> 24.999 | D5: 24.541 | E5: =1-(C5-D5)/(C5-B5) -> 0.11923077 | H5: =B5 -> 24.479 | I5: =C5*(1+Moisture!$J$8/100) -> 25.005426 | J5: =D5 -> 24.541 | K5: =1-(I5-J5)/(I5-H5) -> 0.11777526
B6: 24.545 | C6: =B6+0.827 -> 25.372 | D6: 24.638 | E6: =1-(C6-D6)/(C6-B6) -> 0.11245466 | H6: =B6 -> 24.545 | I6: =C6*(1+Moisture!$J$8/100) -> 25.378522 | J6: =D6 -> 24.638 | K6: =1-(I6-J6)/(I6-H6) -> 0.11157471
B7: 24.129 | C7: =B7+0.932 -> 25.061 | D7: 24.238 | E7: =1-(C7-D7)/(C7-B7) -> 0.11695279 | H7: =B7 -> 24.129 | I7: =C7*(1+Moisture!$J$8/100) -> 25.067442 | J7: =D7 -> 24.238 | K7: =1-(I7-J7)/(I7-H7) -> 0.11614992
E8: =AVERAGE(E5:E7) -> 0.11621274 | F8: stb | K8: =AVERAGE(K5:K7) -> 0.11516663 | L8: stb
D9: av. | E9: =E8/(1-Moisture!J8) -> 0.11927897 | F9: dry | J9: av. | K9: =K8/(1-Moisture!J8) -> 0.11820527 | L9: dry
D10: dev. | E10: =_xlfn.STDEV.P(E5:E7)/(1-Moisture!J8) -> 0.0028896799 | J10: dev. | K10: =_xlfn.STDEV.P(K5:K7)/(1-Moisture!J8) -> 0.0026943799
B11: =Moisture!B11 -> Secco 2 | H11: =Moisture!B11 -> Secco 2
B12: Tare [g] | C12: Gross before [g] | D12: Gross after [g] | E12: Ash | H12: Tare [g] | I12: Gross before [g] | J12: Gross after [g] | K12: Ash
B13: 24.269 | C13: =B13+0.667 -> 24.936 | D13: 24.365 | E13: =1-(C13-D13)/(C13-B13) -> 0.14392804 | H13: =B13 -> 24.269 | I13: =C13*(1+Moisture!$J$16/100) -> 24.943562 | J13: =D13 -> 24.365 | K13: =1-(I13-J13)/(I13-H13) -> 0.14231466
B14: 24.728 | C14: =B14+0.706 -> 25.434 | D14: 24.832 | E14: =1-(C14-D14)/(C14-B14) -> 0.14730878 | H14: =B14 -> 24.728 | I14: =C14*(1+Moisture!$J$16/100) -> 25.441713 | J14: =D14 -> 24.832 | K14: =1-(I14-J14)/(I14-H14) -> 0.14571692
B15: 24.017 | C15: =B15+0.906 -> 24.923 | D15: 24.142 | E15: =1-(C15-D15)/(C15-B15) -> 0.13796909 | H15: =B15 -> 24.017 | I15: =C15*(1+Moisture!$J$16/100) -> 24.930558 | J15: =D15 -> 24.142 | K15: =1-(I15-J15)/(I15-H15) -> 0.13682771
E16: =AVERAGE(E13:E15) -> 0.14306864 | F16: stb | K16: =AVERAGE(K13:K15) -> 0.14161977 | L16: stb
D17: av. | E17: =E16/(1-Moisture!J16) -> 0.1475427 | F17: dry | J17: av. | K17: =K16/(1-Moisture!J16) -> 0.14604852 | L17: dry
D18: dev. | E18: =_xlfn.STDEV.P(E13:E15)/(1-Moisture!J16) -> 0.0039817757 | J18: dev. | K18: =_xlfn.STDEV.P(K13:K15)/(1-Moisture!J16) -> 0.0037766412
B19: =Moisture!B19 -> Umido 1 | H19: =Moisture!B19 -> Umido 1
B20: Tare [g] | C20: Gross before [g] | D20: Gross after [g] | E20: Ash | H20: Tare [g] | I20: Gross before [g] | J20: Gross after [g] | K20: Ash
B21: 23.499 | C21: =B21+0.513 -> 24.012 | D21: 23.522 | E21: =1-(C21-D21)/(C21-B21) -> 0.044834308 | H21: 24.5671 | I21: =H21+0.6316 -> 25.1987 | J21: 24.6184 | K21: =1-(I21-J21)/(I21-H21) -> 0.081222293
B22: 25.135 | C22: =B22+0.535 -> 25.67 | D22: 25.168 | E22: =1-(C22-D22)/(C22-B22) -> 0.061682243 | H22: 25.3876 | I22: =H22+0.9626 -> 26.3502 | J22: 25.4485 | K22: =1-(I22-J22)/(I22-H22) -> 0.063266154
B23: 24.928 | C23: 25.4 | D23: 24.95 | E23: =1-(C23-D23)/(C23-B23) -> 0.046610169 | H23: 24.5433 | I23: =H23+1.0733 -> 25.6166 | J23: 24.6006 | K23: =1-(I23-J23)/(I23-H23) -> 0.053386751
E24: =AVERAGE(E21:E22) -> 0.053258275 | F24: stb | K24: =AVERAGE(K21:K23) -> 0.065958399 | L24: stb
D25: av. | E25: =E24/(1-Moisture!J24) -> 0.055261453 | F25: dry | J25: av. | K25: =K24/(1-Moisture!J24) -> 0.06843926 | L25: dry
D26: dev. | E26: =_xlfn.STDEV.P(E21:E22)/(1-Moisture!J24) -> 0.008740814 | J26: dev. | K26: =_xlfn.STDEV.P(K21:K23)/(1-Moisture!J24) -> 0.011955544
B27: =Moisture!B27 -> Umido 2 | H27: =Moisture!B27 -> Umido 2
B28: Tare [g] | C28: Gross before [g] | D28: Gross after [g] | E28: Ash | H28: Tare [g] | I28: Gross before [g] | J28: Gross after [g] | K28: Ash
B29: 26.141 | C29: =B29+0.523 -> 26.664 | D29: 26.22 | E29: =1-(C29-D29)/(C29-B29) -> 0.15105163 | H29: =B29 -> 26.141 | I29: =C29*(1+Moisture!$J$32/100) -> 26.668068 | J29: =D29 -> 26.22 | K29: =1-(I29-J29)/(I29-H29) -> 0.14988573
B30: 24.575 | C30: =B30+0.529 -> 25.104 | D30: 24.654 | E30: =1-(C30-D30)/(C30-B30) -> 0.14933837 | H30: =B30 -> 24.575 | I30: =C30*(1+Moisture!$J$32/100) -> 25.10783 | J30: =D30 -> 24.654 | K30: =1-(I30-J30)/(I30-H30) -> 0.14826488
B31: 25.389 | C31: =B31+0.324 -> 25.713 | D31: 25.444 | E31: =1-(C31-D31)/(C31-B31) -> 0.16975309 | H31: =B31 -> 25.389 | I31: =C31*(1+Moisture!$J$32/100) -> 25.716923 | J31: =D31 -> 25.444 | K31: =1-(I31-J31)/(I31-H31) -> 0.16772226
E32: =AVERAGE(E29:E31) -> 0.15671436 | F32: stb | K32: =AVERAGE(K29:K31) -> 0.15529096 | L32: stb
D33: av. | E33: =E32/(1-Moisture!J32) -> 0.15914243 | F33: dry | J33: av. | K33: =K32/(1-Moisture!J32) -> 0.15769697 | L33: dry
D34: dev. | E34: =_xlfn.STDEV.P(E29:E31)/(1-Moisture!J32) -> 0.0093895205 | J34: dev. | K34: =_xlfn.STDEV.P(K29:K31)/(1-Moisture!J32) -> 0.0089517064
B35: =Moisture!B35 -> Fanghi 1 | H35: =Moisture!B35 -> Fanghi 1
B36: Tare [g] | C36: Gross before [g] | D36: Gross after [g] | E36: Ash | H36: Tare [g] | I36: Gross before [g] | J36: Gross after [g] | K36: Ash
B37: 1 | C37: 2 | D37: 1 | E37: =1-(C37-D37)/(C37-B37) -> 0 | H37: 24.0165 | I37: =H37+1.0098 -> 25.0263 | J37: 24.1111 | K37: =1-(I37-J37)/(I37-H37) -> 0.093681917
B38: 1 | C38: 2 | D38: 1 | E38: =1-(C38-D38)/(C38-B38) -> 0 | H38: 24.4787 | I38: =H38+0.6489 -> 25.1276 | J38: 24.5417 | K38: =1-(I38-J38)/(I38-H38) -> 0.097087379
B39: 1 | C39: 2 | D39: 1 | E39: =1-(C39-D39)/(C39-B39) -> 0 | H39: 24.7284 | I39: =H39+0.9077 -> 25.6361 | J39: 24.8169 | K39: =1-(I39-J39)/(I39-H39) -> 0.097499174
E40: =AVERAGE(E37:E39) -> 0 | F40: stb | K40: =AVERAGE(K37:K39) -> 0.09608949 | L40: stb
D41: av. | E41: =E40/(1-Moisture!J40) -> 0 | F41: dry | J41: av. | K41: =K40/(1-Moisture!J40) -> 0.09913278 | L41: dry
...

Sheet CHNS
B1: Dry basis +++ remember to set the moisture of the stabilized sample in the CHNS software! +++
B3: =Moisture!B3 -> Secco 1
B4: C [%] | C4: H [%] | D4: N [%] | E4: S [%] | F4: O [%]
B5: 47.33 | C5: 6.623 | D5: 2.44 | E5: 0.714
B6: 45.81 | C6: 6.409 | D6: 2.62 | E6: 0.614
B7: 47.38 | C7: 6.823 | D7: 2.7 | E7: 0.444
A8: av. | B8: =AVERAGE(B5:B7) -> 46.84 | C8: =AVERAGE(C5:C7) -> 6.6183333 | D8: =AVERAGE(D5:D7) -> 2.5866667 | E8: =AVERAGE(E5:E7) -> 0.59066667 | F8: =(1-SUM(B8:E8)/100-Ash!E9)*100 -> 31.436436
A9: dev. | B9: =_xlfn.STDEV.P(B5:B7) -> 0.72860597 | C9: =_xlfn.STDEV.P(C5:C7) -> 0.169047 | D9: =_xlfn.STDEV.P(D5:D7) -> 0.10873004 | E9: =_xlfn.STDEV.P(E5:E7) -> 0.11145502
B11: =Moisture!B11 -> Secco 2
B12: C [%] | C12: H [%] | D12: N [%] | E12: S [%] | F12: O [%]
B13: 44.23 | C13: 6.167 | D13: 2.68 | E13: 0.514
B14: 42.57 | C14: 5.853 | D14: 2.5 | E14: 0.434
B15: 42.65 | C15: 5.884 | D15: 2.65 | E15: 0.429
A16: av. | B16: =AVERAGE(B13:B15) -> 43.15 | C16: =AVERAGE(C13:C15) -> 5.968 | D16: =AVERAGE(D13:D15) -> 2.61 | E16: =AVERAGE(E13:E15) -> 0.459 | F16: =(1-SUM(B16:E16)/100-Ash!E17)*100 -> 33.05873
A17: dev. | B17: =_xlfn.STDEV.P(B13:B15) -> 0.76437338 | C17: =_xlfn.STDEV.P(C13:C15) -> 0.14128222 | D17: =_xlfn.STDEV.P(D13:D15) -> 0.078740079 | E17: =_xlfn.STDEV.P(E13:E15) -> 0.038944405
B19: =Moisture!B19 -> Umido 1
B20: C [%] | C20: H [%] | D20: N [%] | E20: S [%] | F20: O [%]
B21: 49.07 | C21: 6.781 | D21: 1.5 | E21: 0.401
B22: 46.45 | C22: 6.351 | D22: 2.28 | E22: 0.689
B23: 49.27 | C23: 6.674 | D23: 1.89 | E23: 0.527
A24: av. | B24: =AVERAGE(B21:B23) -> 48.263333 | C24: =AVERAGE(C21:C23) -> 6.602 | D24: =AVERAGE(D21:D23) -> 1.89 | E24: =AVERAGE(E21:E23) -> 0.539 | F24: =(1-SUM(B24:E24)/100-Ash!E25)*100 -> 37.179521
A25: dev. | B25: =_xlfn.STDEV.P(B21:B23) -> 1.2848173 | C25: =_xlfn.STDEV.P(C21:C23) -> 0.18278038 | D25: =_xlfn.STDEV.P(D21:D23) -> 0.31843367 | E25: =_xlfn.STDEV.P(E21:E23) -> 0.1178813
B27: =Moisture!B27 -> Umido 2
B28: C [%] | C28: H [%] | D28: N [%] | E28: S [%] | F28: O [%]
B29: 42.48 | C29: 6.112 | D29: 3.02 | E29: 0.693
B30: 41.8 | C30: 5.985 | D30: 3.04 | E30: 0.836
B31: 41.04 | C31: 5.858 | D31: 3.18 | E31: 1.03
A32: av. | B32: =AVERAGE(B29:B31) -> 41.773333 | C32: =AVERAGE(C29:C31) -> 5.985 | D32: =AVERAGE(D29:D31) -> 3.08 | E32: =AVERAGE(E29:E31) -> 0.853 | F32: =(1-SUM(B32:E32)/100-Ash!E33)*100 -> 32.394424
A33: dev. | B33: =_xlfn.STDEV.P(B29:B31) -> 0.58817987 | C33: =_xlfn.STDEV.P(C29:C31) -> 0.10369507 | D33: =_xlfn.STDEV.P(D29:D31) -> 0.071180522 | E33: =_xlfn.STDEV.P(E29:E31) -> 0.13810383
B35: =Moisture!B35 -> Fanghi 1
B36: C [%] | C36: H [%] | D36: N [%] | E36: S [%] | F36: O [%]
B37: 45.29 | C37: 7.028 | D37: 6.06 | E37: 1.233
B38: 45.43 | C38: 7.081 | D38: 5.92 | E38: 1.326
B39: 44.94 | C39: 6.964 | D39: 5.73 | E39: 1.257
A40: av. | B40: =AVERAGE(B37:B39) -> 45.22 | C40: =AVERAGE(C37:C39) -> 7.0243333 | D40: =AVERAGE(D37:D39) -> 5.9033333 | E40: =AVERAGE(E37:E39) -> 1.272 | F40: =(1-SUM(B40:E40)/100-Ash!E41)*100 -> 40.580333
A41: dev. | B41: =_xlfn.STDEV.P(B37:B39) -> 0.20607442 | C41: =_xlfn.STDEV.P(C37:C39) -> 0.047835366 | D41: =_xlfn.STDEV.P(D37:D39) -> 0.13523642 | E41: =_xlfn.STDEV.P(E37:E39) -> 0.039420807
B43: =Moisture!B43 -> Fanghi 2
B44: C [%] | C44: H [%] | D44: N [%] | E44: S [%] | F44: O [%]
B45: 45.99 | C45: 7.341 | D45: 6.04 | E45: 1.301
B46: 45.18 | C46: 7.11 | D46: 5.87 | E46: 1.33
...

Sheet Heating Value
B1: stabilized samples
C2: moisture (stb) | D2: =Moisture!J8 -> 0.025706424
B3: =Moisture!B3 -> Secco 1 | C3: H (dry) | D3: =CHNS!C8/100 -> 0.066183333
B4: HHVstb [MJ/kg] | C4: HHVdry [MJ/kg] | D4: LHVdry [MJ/kg]
B5: 18.297 | C5: =IF(ISBLANK(B5),"",B5/(1-D2)) -> 18.77976 | D5: =IF(ISBLANK(B5),"",C5-2.443*8.936*D3) -> 17.334935
B6: 18.271 | C6: =IF(ISBLANK(B6),"",B6/(1-D2)) -> 18.753074 | D6: =IF(ISBLANK(B6),"",C6-2.443*8.936*D3) -> 17.308249
B7: 18.268 | C7: =IF(ISBLANK(B7),"",B7/(1-D2)) -> 18.749995 | D7: =IF(ISBLANK(B7),"",C7-2.443*8.936*D3) -> 17.30517
A8: av. | B8: =AVERAGE(B5:B7) -> 18.278667 | C8: =AVERAGE(C5:C7) -> 18.760943 | D8: =AVERAGE(D5:D7) -> 17.316118
A9: dev. | B9: =_xlfn.STDEV.P(B5:B7) -> 0.01302135 | C9: =_xlfn.STDEV.P(C5:C7) -> 0.013364914 | D9: =_xlfn.STDEV.P(D5:D7) -> 0.013364914
C10: moisture (stb) | D10: =Moisture!J16 -> 0.030323861
B11: =Moisture!B11 -> Secco 2 | C11: H (dry) | D11: =CHNS!C16/100 -> 0.05968
B12: HHVstb [MJ/kg] | C12: HHVdry [MJ/kg] | D12: LHVdry [MJ/kg]
B13: 16.446 | C13: =IF(ISBLANK(B13),"",B13/(1-D10)) -> 16.960302 | D13: =IF(ISBLANK(B13),"",C13-2.443*8.936*D11) -> 15.657449
B14: 17.119 | C14: =IF(ISBLANK(B14),"",B14/(1-D10)) -> 17.654348 | D14: =IF(ISBLANK(B14),"",C14-2.443*8.936*D11) -> 16.351495
B15: 17.266 | C15: =IF(ISBLANK(B15),"",B15/(1-D10)) -> 17.805945 | D15: =IF(ISBLANK(B15),"",C15-2.443*8.936*D11) -> 16.503092 | E15: 14.8
A16: av. | B16: =AVERAGE(B13:B15) -> 16.943667 | C16: =AVERAGE(C13:C15) -> 17.473532 | D16: =AVERAGE(D13:D15) -> 16.170679
A17: dev. | B17: =_xlfn.STDEV.P(B13:B15) -> 0.35698397 | C17: =_xlfn.STDEV.P(C13:C15) -> 0.36814763 | D17: =_xlfn.STDEV.P(D13:D15) -> 0.36814763
C18: moisture (stb) | D18: =Moisture!J24 -> 0.036249084
B19: =Moisture!B19 -> Umido 1 | C19: H (dry) | D19: =CHNS!C24/100 -> 0.06602
B20: HHVstb [MJ/kg] | C20: HHVdry [MJ/kg] | D20: LHVdry [MJ/kg]
B21: 26.116 | C21: =IF(ISBLANK(B21),"",B21/(1-D18)) -> 27.098288 | D21: =IF(ISBLANK(B21),"",C21-2.443*8.936*D19) -> 25.657029
B22: 23.453 | C22: =IF(ISBLANK(B22),"",B22/(1-D18)) -> 24.335126 | D22: =IF(ISBLANK(B22),"",C22-2.443*8.936*D19) -> 22.893867
B23: 26.536 | C23: =IF(ISBLANK(B23),"",B23/(1-D18)) -> 27.534085 | D23: =IF(ISBLANK(B23),"",C23-2.443*8.936*D19) -> 26.092826
A24: av. | B24: =AVERAGE(B21:B23) -> 25.368333 | C24: =AVERAGE(C21:C23) -> 26.3225 | D24: =AVERAGE(D21:D23) -> 24.88124
A25: dev. | B25: =_xlfn.STDEV.P(B21:B23) -> 1.365156 | C25: =_xlfn.STDEV.P(C21:C23) -> 1.4165029 | D25: =_xlfn.STDEV.P(D21:D23) -> 1.4165029
C26: moisture (stb) | D26: =Moisture!J32 -> 0.015257206
B27: =Moisture!B27 -> Umido 2 | C27: H (dry) | D27: =CHNS!C32/100 -> 0.05985
B28: HHVstb [MJ/kg] | C28: HHVdry [MJ/kg] | D28: LHVdry [MJ/kg]
B29: 16.212 | C29: =IF(ISBLANK(B29),"",B29/(1-D26)) -> 16.463182 | D29: =IF(ISBLANK(B29),"",C29-2.443*8.936*D27) -> 15.156618
B30: 16.113 | C30: =IF(ISBLANK(B30),"",B30/(1-D26)) -> 16.362648 | D30: =IF(ISBLANK(B30),"",C30-2.443*8.936*D27) -> 15.056084
B31: 16.192 | C31: =IF(ISBLANK(B31),"",B31/(1-D26)) -> 16.442872 | D31: =IF(ISBLANK(B31),"",C31-2.443*8.936*D27) -> 15.136308
A32: av. | B32: =AVERAGE(B29:B31) -> 16.172333 | C32: =AVERAGE(C29:C31) -> 16.422901 | D32: =AVERAGE(D29:D31) -> 15.116337
A33: dev. | B33: =_xlfn.STDEV.P(B29:B31) -> 0.042742121 | C33: =_xlfn.STDEV.P(C29:C31) -> 0.04340435 | D33: =_xlfn.STDEV.P(D29:D31) -> 0.04340435
C34: moisture (stb) | D34: =Moisture!J40 -> 0.030699127
B35: =Moisture!B35 -> Fanghi 1 | C35: H (dry) | D35: =CHNS!C40/100 -> 0.070243333
B36: HHVstb [MJ/kg] | C36: HHVdry [MJ/kg] | D36: LHVdry [MJ/kg]
B37: 18.349 | C37: =IF(ISBLANK(B37),"",B37/(1-D34)) -> 18.930139 | D37: =IF(ISBLANK(B37),"",C37-2.443*8.936*D35) -> 17.396681
B38: 18.392 | C38: =IF(ISBLANK(B38),"",B38/(1-D34)) -> 18.974501 | D38: =IF(ISBLANK(B38),"",C38-2.443*8.936*D35) -> 17.441043
B39: 18.273 | C39: =IF(ISBLANK(B39),"",B39/(1-D34)) -> 18.851732 | D39: =IF(ISBLANK(B39),"",C39-2.443*8.936*D35) -> 17.318274
A40: av. | B40: =AVERAGE(B37:B39) -> 18.338 | C40: =AVERAGE(C37:C39) -> 18.91879 | D40: =AVERAGE(D37:D39) -> 17.385333
...

Sheet Ultimate analysis
B3: =Moisture!B3 -> Secco 1 | I3: =Moisture!B11 -> Secco 2 | P3: =Moisture!B19 -> Umido 1
D4: ar | E4: stb | F4: dry | G4: daf | K4: ar | L4: stb | M4: dry | N4: daf | R4: ar | S4: stb | T4: dry | U4: daf
B5: moisture | C5: %wt | D5: =Moisture!E8*100 -> 6.6267058 | E5: =Moisture!J8*100 -> 2.5706424 | F5: - | G5: - | I5: moisture | J5: %wt | K5: =Moisture!E16*100 -> 12.674288 | L5: =Moisture!J16*100 -> 3.0323861 | M5: - | N5: - | P5: moisture | Q5: %wt | R5: =Moisture!E24*100 -> 78.125147 | S5: =Moisture!J24*100 -> 3.6249084 | T5: - | U5: -
B6: ash | C6: %wt | D6: =F6*(1-D5/100) -> 11.037215 | E6: =F6*(1-E5/100) -> 11.516663 | F6: =Ash!K9*100 -> 11.820527 | G6: - | I6: ash | J6: %wt | K6: =M6*(1-K5/100) -> 12.753791 | L6: =M6*(1-L5/100) -> 14.161977 | M6: =Ash!K17*100 -> 14.604852 | N6: - | P6: ash | Q6: %wt | R6: =T6*(1-R5/100) -> 1.4970987 | S6: =T6*(1-S5/100) -> 6.5958399 | T6: =Ash!K25*100 -> 6.843926 | U6: -
B8: C | C8: %wt | D8: =F8*(1-D5/100) -> 43.736051 | E8: =F8*(1-E5/100) -> 45.635911 | F8: =CHNS!B8 -> 46.84 | G8: =F8/(1-F$6/100) -> 53.118938 | I8: C | J8: %wt | K8: =M8*(1-K5/100) -> 37.681045 | L8: =M8*(1-L5/100) -> 41.841525 | M8: =CHNS!B16 -> 43.15 | N8: =M8/(1-M$6/100) -> 50.529803 | P8: C | Q8: %wt | R8: =T8*(1-R5/100) -> 10.557533 | S8: =T8*(1-S5/100) -> 46.513832 | T8: =CHNS!B24 -> 48.263333 | U8: =T8/(1-T$6/100) -> 51.809111
B9: H | C9: %wt | D9: =F9*(1-D5/100) -> 6.1797559 | E9: =F9*(1-E5/100) -> 6.4481996 | F9: =CHNS!C8 -> 6.6183333 | G9: =F9/(1-F$6/100) -> 7.505526 | I9: H | J9: %wt | K9: =M9*(1-K5/100) -> 5.2115985 | L9: =M9*(1-L5/100) -> 5.7870272 | M9: =CHNS!C16 -> 5.968 | N9: =M9/(1-M$6/100) -> 6.9886875 | P9: H | Q9: %wt | R9: =T9*(1-R5/100) -> 1.4441778 | S9: =T9*(1-S5/100) -> 6.3626835 | T9: =CHNS!C24 -> 6.602 | U9: =T9/(1-T$6/100) -> 7.0870312
B10: O | C10: %wt | D10: =F10*(1-D5/100) -> 29.453492 | E10: =F10*(1-E5/100) -> 30.732928 | F10: =100-SUM(F6:F9,F11:F12) -> 31.543807 | G10: =F10/(1-F$6/100) -> 35.772278 | I10: O | J10: %wt | K10: =M10*(1-K5/100) -> 28.999252 | L10: =M10*(1-L5/100) -> 32.201149 | M10: =100-SUM(M6:M9,M11:M12) -> 33.208148 | N10: =M10/(1-M$6/100) -> 38.887629 | P10: O | Q10: %wt | R10: =T10*(1-R5/100) -> 7.844703 | S10: =T10*(1-S5/100) -> 34.561785 | T10: =100-SUM(T6:T9,T11:T12) -> 35.861741 | U10: =T10/(1-T$6/100) -> 38.496406
B11: N | C11: %wt | D11: =F11*(1-D5/100) -> 2.4152559 | E11: =F11*(1-E5/100) -> 2.5201727 | F11: =CHNS!D8 -> 2.5866667 | G11: =F11/(1-F$6/100) -> 2.9334113 | I11: N | J11: %wt | K11: =M11*(1-K5/100) -> 2.2792011 | L11: =M11*(1-L5/100) -> 2.5308547 | M11: =CHNS!D16 -> 2.61 | N11: =M11/(1-M$6/100) -> 3.0563797 | P11: N | Q11: %wt | R11: =T11*(1-R5/100) -> 0.41343472 | S11: =T11*(1-S5/100) -> 1.8214892 | T11: =CHNS!D24 -> 1.89 | U11: =T11/(1-T$6/100) -> 2.0288532
B12: S | C12: %wt | D12: =F12*(1-D5/100) -> 0.55152492 | E12: =F12*(1-E5/100) -> 0.57548274 | F12: =CHNS!E8 -> 0.59066667 | G12: =F12/(1-F$6/100) -> 0.66984599 | I12: S | J12: %wt | K12: =M12*(1-K5/100) -> 0.40082502 | L12: =M12*(1-L5/100) -> 0.44508135 | M12: =CHNS!E16 -> 0.459 | N12: =M12/(1-M$6/100) -> 0.53750126 | P12: S | Q12: %wt | R12: =T12*(1-R5/100) -> 0.11790546 | S12: =T12*(1-S5/100) -> 0.51946174 | T12: =CHNS!E24 -> 0.539 | U12: =T12/(1-T$6/100) -> 0.57859888
B14: HHV | C14: MJ/kg | D14: =F14*(1-D5/100) -> 17.517711 | E14: =F14*(1-E5/100) -> 18.278667 | F14: ='Heating Value'!C8 -> 18.760943 | G14: =F14/(1-F6/100) -> 21.275862 | I14: HHV | J14: MJ/kg | K14: =M14*(1-K5/100) -> 15.258886 | L14: =M14*(1-L5/100) -> 16.943667 | M14: ='Heating Value'!C16 -> 17.473532 | N14: =M14/(1-M6/100) -> 20.461972 | P14: HHV | Q14: MJ/kg | R14: =T14*(1-R5/100) -> 5.7580081 | S14: =T14*(1-S5/100) -> 25.368333 | T14: ='Heating Value'!C24 -> 26.3225 | U14: =T14/(1-T6/100) -> 28.256343
B15: LHV | C15: MJ/kg | D15: =D14-2.442*(8.936*F9/100*(1-D5/100)+D5/100) -> 16.007358 | E15: =E14-2.442*(8.936*F9/100*(1-E5/100)+E5/100) -> 16.808784 | F15: =F14-2.442*8.936*F9/100 -> 17.31671 | G15: =F15/(1-F6/100) -> 19.638028 | I15: LHV | J15: MJ/kg | K15: =K14-2.442*(8.936*M9/100*(1-K5/100)+K5/100) -> 13.81212 | L15: =L14-2.442*(8.936*M9/100*(1-L5/100)+L5/100) -> 15.606787 | M15: =M14-2.442*8.936*M9/100 -> 16.171212 | N15: =M15/(1-M6/100) -> 18.936921 | P15: LHV | Q15: MJ/kg | R15: =R14-2.442*(8.936*T9/100*(1-R5/100)+R5/100) -> 3.5350477 | S15: =S14-2.442*(8.936*T9/100*(1-S5/100)+S5/100) -> 23.891367 | T15: =T14-2.442*8.936*T9/100 -> 24.88183 | U15: =T15/(1-T6/100) -> 26.709832
B17: HHVMilne | C17: MJ/kg | D17: =F17*(1-D5/100) -> 19.128346 | E17: =F17*(1-E5/100) -> 19.959267 | F17: =0.341*F8+1.322*F9-0.12*F10-0.12*F11+0.0686*F12-0.0153*F6 -> 20.485886 | G17: =F17/(1-F6/100) -> 23.232034 | I17: HHVMilne | J17: MJ/kg | K17: =M17*(1-K5/100) -> 15.817919 | L17: =M17*(1-L5/100) -> 17.564424 | M17: =0.341*M8+1.322*M9-0.12*M10-0.12*M11+0.0686*M12-0.0153*M6 -> 18.113701 | N17: =M17/(1-M6/100) -> 21.211628 | P17: HHVMilne | Q17: MJ/kg | R17: =T17*(1-R5/100) -> 4.503528 | S17: =T17*(1-S5/100) -> 19.84141 | T17: =0.341*T8+1.322*T9-0.12*T10-0.12*T11+0.0686*T12-0.0153*T6 -> 20.587695 | U17: =T17/(1-T6/100) -> 22.100218
B18: LHVMilne | C18: MJ/kg | D18: =D17-2.442*(8.936*F9/100*(1-D5/100)+D5/100) -> 17.617993 | E18: =E17-2.442*(8.936*F9/100*(1-E5/100)+E5/100) -> 18.489384 | F18: =F17-2.442*8.936*F9/100 -> 19.041652 | G18: =F18/(1-F6/100) -> 21.5942 | I18: LHVMilne | J18: MJ/kg | K18: =K17-2.442*(8.936*M9/100*(1-K5/100)+K5/100) -> 14.371153 | L18: =L17-2.442*(8.936*M9/100*(1-L5/100)+L5/100) -> 16.227545 | M18: =M17-2.442*8.936*M9/100 -> 16.811382 | N18: =M18/(1-M6/100) -> 19.686577 | P18: LHVMilne | Q18: MJ/kg | R18: =R17-2.442*(8.936*T9/100*(1-R5/100)+R5/100) -> 2.2805676 | S18: =S17-2.442*(8.936*T9/100*(1-S5/100)+S5/100) -> 18.364443 | T18: =T17-2.442*8.936*T9/100 -> 19.147026 | U18: =T18/(1-T6/100) -> 20.553706
B21: =Moisture!B27 -> Umido 2 | I21: =Moisture!B35 -> Fanghi 1 | P21: =Moisture!B43 -> Fanghi 2
D22: ar | E22: stb | F22: dry | G22: daf | K22: ar | L22: stb | M22: dry | N22: daf | R22: ar | S22: stb | T22: dry | U22: daf
B23: moisture | C23: %wt | D23: =Moisture!E32*100 -> 70.281634 | E23: =Moisture!J32*100 -> 1.5257206 | F23: - | G23: - | I23: moisture | J23: %wt | K23: =Moisture!E40*100 -> 85.16965 | L23: =Moisture!J40*100 -> 3.0699127 | M23: - | N23: - | P23: moisture | Q23: %wt | R23: =Moisture!E48*100 -> 86.032907 | S23: =Moisture!J48*100 -> 2.6301593 | T23: - | U23: -
B24: ash | C24: %wt | D24: =F24*(1-D23/100) -> 4.6864963 | E24: =F24*(1-E23/100) -> 15.529096 | F24: =Ash!K33*100 -> 15.769697 | G24: - | I24: ash | J24: %wt | K24: =M24*(1-K23/100) -> 1.4701738 | L24: =M24*(1-L23/100) -> 9.608949 | M24: =Ash!K41*100 -> 9.913278 | N24: - | P24: ash | Q24: %wt | R24: =T24*(1-R23/100) -> 1.3466278 | S24: =T24*(1-S23/100) -> 9.3878472 | T24: =Ash!K49*100 -> 9.6414323 | U24: -
B26: C | C26: %wt | D26: =F26*(1-D23/100) -> 12.414352 | E26: =F26*(1-E23/100) -> 41.135989 | F26: =CHNS!B32 -> 41.773333 | G26: =F26/(1-F$24/100) -> 49.594186 | I26: C | J26: %wt | K26: =M26*(1-K23/100) -> 6.7062842 | L26: =M26*(1-L23/100) -> 43.831785 | M26: =CHNS!B40 -> 45.22 | N26: =M26/(1-M$24/100) -> 50.196077 | P26: C | Q26: %wt | R26: =T26*(1-R23/100) -> 6.3606141 | S26: =T26*(1-S23/100) -> 44.342225 | T26: =CHNS!B48 -> 45.54 | U26: =T26/(1-T$24/100) -> 50.399205
B27: H | C27: %wt | D27: =F27*(1-D23/100) -> 1.7786442 | E27: =F27*(1-E23/100) -> 5.8936856 | F27: =CHNS!C32 -> 5.985 | G27: =F27/(1-F$24/100) -> 7.1055188 | I27: H | J27: %wt | K27: =M27*(1-K23/100) -> 1.0417332 | L27: =M27*(1-L23/100) -> 6.8086924 | M27: =CHNS!C40 -> 7.0243333 | N27: =M27/(1-M$24/100) -> 7.7973015 | P27: H | Q27: %wt | R27: =T27*(1-R23/100) -> 1.0069343 | S27: =T27*(1-S23/100) -> 7.0197164 | T27: =CHNS!C48 -> 7.2093333 | U27: =T27/(1-T$24/100) -> 7.978583
B28: O | C28: %wt | D28: =F28*(1-D23/100) -> 9.6700501 | E28: =F28*(1-E23/100) -> 32.042516 | F28: =100-SUM(F24:F27,F29:F30) -> 32.53897 | G28: =F28/(1-F$24/100) -> 38.630954 | I28: O | J28: %wt | K28: =M28*(1-K23/100) -> 4.5480316 | L28: =M28*(1-L23/100) -> 29.725604 | M28: =100-SUM(M24:M27,M29:M30) -> 30.667055 | N28: =M28/(1-M$24/100) -> 34.041704 | P28: O | Q28: %wt | R28: =T28*(1-R23/100) -> 4.2462152 | S28: =T28*(1-S23/100) -> 29.601958 | T28: =100-SUM(T24:T27,T29:T30) -> 30.401568 | U28: =T28/(1-T$24/100) -> 33.645473
B29: N | C29: %wt | D29: =F29*(1-D23/100) -> 0.91532568 | E29: =F29*(1-E23/100) -> 3.0330078 | F29: =CHNS!D32 -> 3.08 | G29: =F29/(1-F$24/100) -> 3.6566412 | I29: N | J29: %wt | K29: =M29*(1-K23/100) -> 0.87548498 | L29: =M29*(1-L23/100) -> 5.7221062 | M29: =CHNS!D40 -> 5.9033333 | N29: =M29/(1-M$24/100) -> 6.552945 | P29: N | Q29: %wt | R29: =T29*(1-R23/100) -> 0.82545519 | S29: =T29*(1-S23/100) -> 5.7545576 | T29: =CHNS!D48 -> 5.91 | U29: =T29/(1-T$24/100) -> 6.5406083
B30: S | C30: %wt | D30: =F30*(1-D23/100) -> 0.25349766 | E30: =F30*(1-E23/100) -> 0.8399856 | F30: =CHNS!E32 -> 0.853 | G30: =F30/(1-F$24/100) -> 1.0126997 | I30: S | J30: %wt | K30: =M30*(1-K23/100) -> 0.18864205 | L30: =M30*(1-L23/100) -> 1.2329507 | M30: =CHNS!E40 -> 1.272 | N30: =M30/(1-M$24/100) -> 1.4119728 | P30: S | Q30: %wt | R30: =T30*(1-R23/100) -> 0.18124631 | S30: =T30*(1-S23/100) -> 1.263536 | T30: =CHNS!E48 -> 1.2976667 | U30: =T30/(1-T$24/100) -> 1.4361302
B32: HHV | C32: MJ/kg | D32: =F32*(1-D23/100) -> 4.8806178 | E32: =F32*(1-E23/100) -> 16.172333 | F32: ='Heating Value'!C32 -> 16.422901 | G32: =F32/(1-F24/100) -> 19.497616 | I32: HHV | J32: MJ/kg | K32: =M32*(1-K23/100) -> 2.8057228 | L32: =M32*(1-L23/100) -> 18.338 | M32: ='Heating Value'!C40 -> 18.91879 | N32: =M32/(1-M24/100) -> 21.000642 | P32: HHV | Q32: MJ/kg | R32: =T32*(1-R23/100) -> 2.6507444 | S32: =T32*(1-S23/100) -> 18.479333 | T32: ='Heating Value'!C48 -> 18.978498 | U32: =T32/(1-T24/100) -> 21.00354
B33: LHV | C33: MJ/kg | D33: =D32-2.442*(8.936*F27/100*(1-D23/100)+D23/100) -> 2.7762097 | E33: =E32-2.442*(8.936*F27/100*(1-E23/100)+E23/100) -> 14.848972 | F33: =F32-2.442*8.936*F27/100 -> 15.116871 | G33: =F33/(1-F24/100) -> 17.94707 | I33: LHV | J33: MJ/kg | K33: =K32-2.442*(8.936*M27/100*(1-K23/100)+K23/100) -> 0.4985559 | L33: =L32-2.442*(8.936*M27/100*(1-L23/100)+L23/100) -> 16.777259 | M33: =M32-2.442*8.936*M27/100 -> 17.385961 | N33: =M33/(1-M24/100) -> 19.299138 | P33: LHV | Q33: MJ/kg | R33: =R32-2.442*(8.936*T27/100*(1-R23/100)+R23/100) -> 0.33009055 | S33: =S32-2.442*(8.936*T27/100*(1-S23/100)+S23/100) -> 16.883283 | T33: =T32-2.442*8.936*T27/100 -> 17.405298 | U33: =T33/(1-T24/100) -> 19.262477
B35: HHVMilne | C35: MJ/kg | D35: =F35*(1-D23/100) -> 5.2601032 | E35: =F35*(1-E23/100) -> 17.42979 | F35: =0.341*F26+1.322*F27-0.12*F28-0.12*F29+0.0686*F30-0.0153*F24 -> 17.69984 | G35: =F35/(1-F24/100) -> 21.013625 | I35: HHVMilne | J35: MJ/kg | K35: =M35*(1-K23/100) -> 3.0036394 | L35: =M35*(1-L23/100) -> 19.631569 | M35: =0.341*M26+1.322*M27-0.12*M28-0.12*M29+0.0686*M30-0.0153*M24 -> 20.253328 | N35: =M35/(1-M24/100) -> 22.482035 | P35: HHVMilne | Q35: MJ/kg | R35: =T35*(1-R23/100) -> 2.8833662 | S35: =T35*(1-S23/100) -> 20.101027 | T35: =0.341*T26+1.322*T27-0.12*T28-0.12*T29+0.0686*T30-0.0153*T24 -> 20.643997 | U35: =T35/(1-T24/100) -> 22.846751
B36: LHVMilne | C36: MJ/kg | D36: =D35-2.442*(8.936*F27/100*(1-D23/100)+D23/100) -> 3.1556951 | E36: =E35-2.442*(8.936*F27/100*(1-E23/100)+E23/100) -> 16.106428 | F36: =F35-2.442*8.936*F27/100 -> 16.39381 | G36: =F36/(1-F24/100) -> 19.463079 | I36: LHVMilne | J36: MJ/kg | K36: =K35-2.442*(8.936*M27/100*(1-K23/100)+K23/100) -> 0.69647252 | L36: =L35-2.442*(8.936*M27/100*(1-L23/100)+L23/100) -> 18.070828 | M36: =M35-2.442*8.936*M27/100 -> 18.720498 | N36: =M36/(1-M24/100) -> 20.78053 | P36: LHVMilne | Q36: MJ/kg | R36: =R35-2.442*(8.936*T27/100*(1-R23/100)+R23/100) -> 0.56271227 | S36: =S35-2.442*(8.936*T27/100*(1-S23/100)+S23/100) -> 18.504976 | T36: =T35-2.442*8.936*T27/100 -> 19.070797 | U36: =T36/(1-T24/100) -> 21.105687

Sheet pivot
A1: Sample | B1: H2O | C1: H2Odev | D1: Ash | E1: Ashdev | F1: C | G1: Cdev | H1: H | I1: Hdev | J1: N | K1: Ndev | L1: S | M1: Sdev | N1: O | O1: HHVdry | P1: HHVdry_dev | Q1: LHVdry | R1: LHVdry_dev | S1: HHVar | U1: LHVar | W1: nota
A2: =Moisture!B3 -> Secco 1 | B2: =TEXT(Moisture!E8*100,"0.00") -> 007 | C2: =TEXT(Moisture!E9*100,"0.00") -> 000 | D2: =TEXT(Ash!E9*100,"0.00") -> 012 | E2: =TEXT(Ash!E10*100,"0.00") -> 000 | F2: =TEXT(CHNS!B8,"0.00") -> 047 | G2: =TEXT(CHNS!B9,"0.00") -> 001 | H2: =TEXT(CHNS!C8,"0.00") -> 007 | I2: =TEXT(CHNS!C9,"0.00") -> 000 | J2: =TEXT(CHNS!D8,"0.00") -> 003 | K2: =TEXT(CHNS!D9,"0.00") -> 000 | L2: =TEXT(CHNS!E8,"0.00") -> 001 | M2: =TEXT(CHNS!E9,"0.00") -> 000 | N2: =IF(CHNS!F8<0,"*",TEXT(CHNS!F8,"0.00")) -> 031 | O2: =TEXT('Heating Value'!C8,"0.00") -> 019 | P2: =TEXT('Heating Value'!C9,"0.00") -> 000 | Q2: =TEXT('Heating Value'!D8,"0.00") -> 017 | R2: =TEXT('Heating Value'!D9,"0.00") -> 000 | S2: =TEXT(O2*(1-B2/100),"0.00") -> 018 | U2: =TEXT(S2-2.442*(8.936*H2/100*(1-B2/100)+B2/100),"0.00") -> 016 | W2: =IF(N2="*","Nota: A causa della natura non omogenea del campione, la somma di CHNS e ceneri su base secca risulta superiore a 100","")
A3: =Moisture!B11 -> Secco 2 | B3: =TEXT(Moisture!E16*100,"0.00") -> 013 | C3: =TEXT(Moisture!E17*100,"0.00") -> 001 | D3: =TEXT(Ash!E17*100,"0.00") -> 015 | E3: =TEXT(Ash!E18*100,"0.00") -> 000 | F3: =TEXT(CHNS!B16,"0.00") -> 043 | G3: =TEXT(CHNS!B17,"0.00") -> 001 | H3: =TEXT(CHNS!C16,"0.00") -> 006 | I3: =TEXT(CHNS!C17,"0.00") -> 000 | J3: =TEXT(CHNS!D16,"0.00") -> 003 | K3: =TEXT(CHNS!D17,"0.00") -> 000 | L3: =TEXT(CHNS!E16,"0.00") -> 000 | M3: =TEXT(CHNS!E17,"0.00") -> 000 | N3: =IF(CHNS!F16<0,"*",TEXT(CHNS!F16,"0.00")) -> 033 | O3: =TEXT('Heating Value'!C16,"0.00") -> 017 | P3: =TEXT('Heating Value'!C17,"0.00") -> 000 | Q3: =TEXT('Heating Value'!D16,"0.00") -> 016 | R3: =TEXT('Heating Value'!D17,"0.00") -> 000 | S3: =TEXT(O3*(1-B3/100),"0.00") -> 015 | U3: =TEXT(S3-2.442*(8.936*H3/100*(1-B3/100)+B3/100),"0.00") -> 014 | W3: =IF(N3="*","Nota: A causa della natura non omogenea del campione, la somma di CHNS e ceneri su base secca risulta superiore a 100","")
A4: =Moisture!B19 -> Umido 1 | B4: =TEXT(Moisture!E24*100,"0.00") -> 078 | C4: =TEXT(Moisture!E25*100,"0.00") -> 001 | D4: =TEXT(Ash!E25*100,"0.00") -> 006 | E4: =TEXT(Ash!E26*100,"0.00") -> 001 | F4: =TEXT(CHNS!B24,"0.00") -> 048 | G4: =TEXT(CHNS!B25,"0.00") -> 001 | H4: =TEXT(CHNS!C24,"0.00") -> 007 | I4: =TEXT(CHNS!C25,"0.00") -> 000 | J4: =TEXT(CHNS!D24,"0.00") -> 002 | K4: =TEXT(CHNS!D25,"0.00") -> 000 | L4: =TEXT(CHNS!E24,"0.00") -> 001 | M4: =TEXT(CHNS!E25,"0.00") -> 000 | N4: =IF(CHNS!F24<0,"*",TEXT(CHNS!F24,"0.00")) -> 037 | O4: =TEXT('Heating Value'!C24,"0.00") -> 026 | P4: =TEXT('Heating Value'!C25,"0.00") -> 001 | Q4: =TEXT('Heating Value'!D24,"0.00") -> 025 | R4: =TEXT('Heating Value'!D25,"0.00") -> 001 | S4: =TEXT(O4*(1-B4/100),"0.00") -> 006 | U4: =TEXT(S4-2.442*(8.936*H4/100*(1-B4/100)+B4/100),"0.00") -> 004 | W4: =IF(N4="*","Nota: A causa della natura non omogenea del campione, la somma di CHNS e ceneri su base secca risulta superiore a 100","")
A5: =Moisture!B27 -> Umido 2 | B5: =TEXT(Moisture!E32*100,"0.00") -> 070 | C5: =TEXT(Moisture!E33*100,"0.00") -> 001 | D5: =TEXT(Ash!E33*100,"0.00") -> 016 | E5: =TEXT(Ash!E34*100,"0.00") -> 001 | F5: =TEXT(CHNS!B32,"0.00") -> 042 | G5: =TEXT(CHNS!B33,"0.00") -> 001 | H5: =TEXT(CHNS!C32,"0.00") -> 006 | I5: =TEXT(CHNS!C33,"0.00") -> 000 | J5: =TEXT(CHNS!D32,"0.00") -> 003 | K5: =TEXT(CHNS!D33,"0.00") -> 000 | L5: =TEXT(CHNS!E32,"0.00") -> 001 | M5: =TEXT(CHNS!E33,"0.00") -> 000 | N5: =IF(CHNS!F32<0,"*",TEXT(CHNS!F32,"0.00")) -> 032 | O5: =TEXT('Heating Value'!C32,"0.00") -> 016 | P5: =TEXT('Heating Value'!C33,"0.00") -> 000 | Q5: =TEXT('Heating Value'!D32,"0.00") -> 015 | R5: =TEXT('Heating Value'!D33,"0.00") -> 000 | S5: =TEXT(O5*(1-B5/100),"0.00") -> 005 | U5: =TEXT(S5-2.442*(8.936*H5/100*(1-B5/100)+B5/100),"0.00") -> 003 | W5: =IF(N5="*","Nota: A causa della natura non omogenea del campione, la somma di CHNS e ceneri su base secca risulta superiore a 100","")
A6: =Moisture!B35 -> Fanghi 1 | B6: =TEXT(Moisture!E40*100,"0.00") -> 085 | C6: =TEXT(Moisture!E41*100,"0.00") -> 000 | D6: =TEXT(Ash!E41*100,"0.00") -> 000 | E6: =TEXT(Ash!E42*100,"0.00") -> 000 | F6: =TEXT(CHNS!B40,"0.00") -> 045 | G6: =TEXT(CHNS!B41,"0.00") -> 000 | H6: =TEXT(CHNS!C40,"0.00") -> 007 | I6: =TEXT(CHNS!C41,"0.00") -> 000 | J6: =TEXT(CHNS!D40,"0.00") -> 006 | K6: =TEXT(CHNS!D41,"0.00") -> 000 | L6: =TEXT(CHNS!E40,"0.00") -> 001 | M6: =TEXT(CHNS!E41,"0.00") -> 000 | N6: =IF(CHNS!F40<0,"*",TEXT(CHNS!F40,"0.00")) -> 041 | O6: =TEXT('Heating Value'!C40,"0.00") -> 019 | P6: =TEXT('Heating Value'!C41,"0.00") -> 000 | Q6: =TEXT('Heating Value'!D40,"0.00") -> 017 | R6: =TEXT('Heating Value'!D41,"0.00") -> 000 | S6: =TEXT(O6*(1-B6/100),"0.00") -> 003 | U6: =TEXT(S6-2.442*(8.936*H6/100*(1-B6/100)+B6/100),"0.00") -> 001 | W6: =IF(N6="*","Nota: A causa della natura non omogenea del campione, la somma di CHNS e ceneri su base secca risulta superiore a 100","")
A7: =Moisture!B43 -> Fanghi 2 | B7: =TEXT(Moisture!E48*100,"0.00") -> 086 | C7: =TEXT(Moisture!E49*100,"0.00") -> 001 | D7: =TEXT(Ash!E49*100,"0.00") -> 000 | E7: =TEXT(Ash!E50*100,"0.00") -> 000 | F7: =TEXT(CHNS!B48,"0.00") -> 046 | G7: =TEXT(CHNS!B49,"0.00") -> 000 | H7: =TEXT(CHNS!C48,"0.00") -> 007 | I7: =TEXT(CHNS!C49,"0.00") -> 000 | J7: =TEXT(CHNS!D48,"0.00") -> 006 | K7: =TEXT(CHNS!D49,"0.00") -> 000 | L7: =TEXT(CHNS!E48,"0.00") -> 001 | M7: =TEXT(CHNS!E49,"0.00") -> 000 | N7: =IF(CHNS!F48<0,"*",TEXT(CHNS!F48,"0.00")) -> 040 | O7: =TEXT('Heating Value'!C48,"0.00") -> 019 | P7: =TEXT('Heating Value'!C49,"0.00") -> 000 | Q7: =TEXT('Heating Value'!D48,"0.00") -> 017 | R7: =TEXT('Heating Value'!D49,"0.00") -> 000 | S7: =TEXT(O7*(1-B7/100),"0.00") -> 003 | U7: =TEXT(S7-2.442*(8.936*H7/100*(1-B7/100)+B7/100),"0.00") -> 001 | W7: =IF(N7="*","Nota: A causa della natura non omogenea del campione, la somma di CHNS e ceneri su base secca risulta superiore a 100","")
